[2024-06-01T18:05:02.574+0000] {taskinstance.py:1083} INFO - Dependencies all met for <TaskInstance: fitbit_data_pull.get_heart_rate scheduled__2024-05-31T18:00:00+00:00 [queued]>
[2024-06-01T18:05:02.579+0000] {taskinstance.py:1083} INFO - Dependencies all met for <TaskInstance: fitbit_data_pull.get_heart_rate scheduled__2024-05-31T18:00:00+00:00 [queued]>
[2024-06-01T18:05:02.580+0000] {taskinstance.py:1279} INFO - 
--------------------------------------------------------------------------------
[2024-06-01T18:05:02.581+0000] {taskinstance.py:1280} INFO - Starting attempt 2 of 2
[2024-06-01T18:05:02.581+0000] {taskinstance.py:1281} INFO - 
--------------------------------------------------------------------------------
[2024-06-01T18:05:02.589+0000] {taskinstance.py:1300} INFO - Executing <Task(PythonOperator): get_heart_rate> on 2024-05-31 18:00:00+00:00
[2024-06-01T18:05:02.594+0000] {standard_task_runner.py:55} INFO - Started process 68760 to run task
[2024-06-01T18:05:02.597+0000] {standard_task_runner.py:82} INFO - Running: ['***', 'tasks', 'run', 'fitbit_data_pull', 'get_heart_rate', 'scheduled__2024-05-31T18:00:00+00:00', '--job-id', '69', '--raw', '--subdir', 'DAGS_FOLDER/fitbit_pull_dag.py', '--cfg-path', '/tmp/tmpxlao4rex']
[2024-06-01T18:05:02.598+0000] {standard_task_runner.py:83} INFO - Job 69: Subtask get_heart_rate
[2024-06-01T18:05:02.648+0000] {task_command.py:388} INFO - Running <TaskInstance: fitbit_data_pull.get_heart_rate scheduled__2024-05-31T18:00:00+00:00 [running]> on host eb426318bb2e
[2024-06-01T18:05:02.692+0000] {taskinstance.py:1509} INFO - Exporting the following env vars:
AIRFLOW_CTX_DAG_OWNER=***
AIRFLOW_CTX_DAG_ID=fitbit_data_pull
AIRFLOW_CTX_TASK_ID=get_heart_rate
AIRFLOW_CTX_EXECUTION_DATE=2024-05-31T18:00:00+00:00
AIRFLOW_CTX_TRY_NUMBER=2
AIRFLOW_CTX_DAG_RUN_ID=scheduled__2024-05-31T18:00:00+00:00
[2024-06-01T18:05:02.974+0000] {taskinstance.py:1768} ERROR - Task failed with exception
Traceback (most recent call last):
  File "/home/airflow/.local/lib/python3.7/site-packages/airflow/operators/python.py", line 175, in execute
    return_value = self.execute_callable()
  File "/home/airflow/.local/lib/python3.7/site-packages/airflow/operators/python.py", line 192, in execute_callable
    return self.python_callable(*self.op_args, **self.op_kwargs)
  File "/opt/airflow/dags/fitbit_pull_dag.py", line 56, in _get_yesterday_heartrate
    df_heartrate = df_heartrate[['date','time','heartrate']]
  File "/home/airflow/.local/lib/python3.7/site-packages/pandas/core/frame.py", line 3464, in __getitem__
    indexer = self.loc._get_listlike_indexer(key, axis=1)[1]
  File "/home/airflow/.local/lib/python3.7/site-packages/pandas/core/indexing.py", line 1314, in _get_listlike_indexer
    self._validate_read_indexer(keyarr, indexer, axis)
  File "/home/airflow/.local/lib/python3.7/site-packages/pandas/core/indexing.py", line 1377, in _validate_read_indexer
    raise KeyError(f"{not_found} not in index")
KeyError: "['time', 'heartrate'] not in index"
[2024-06-01T18:05:02.985+0000] {taskinstance.py:1323} INFO - Marking task as FAILED. dag_id=fitbit_data_pull, task_id=get_heart_rate, execution_date=20240531T180000, start_date=20240601T180502, end_date=20240601T180502
[2024-06-01T18:05:02.992+0000] {standard_task_runner.py:105} ERROR - Failed to execute job 69 for task get_heart_rate ("['time', 'heartrate'] not in index"; 68760)
[2024-06-01T18:05:03.034+0000] {local_task_job.py:208} INFO - Task exited with return code 1
[2024-06-01T18:05:03.049+0000] {taskinstance.py:2578} INFO - 0 downstream tasks scheduled from follow-on schedule check
