[2024-05-16T17:05:01.942+0000] {taskinstance.py:1083} INFO - Dependencies all met for <TaskInstance: fitbit_data_pull.get_heart_rate scheduled__2024-05-15T17:00:00+00:00 [queued]>
[2024-05-16T17:05:01.948+0000] {taskinstance.py:1083} INFO - Dependencies all met for <TaskInstance: fitbit_data_pull.get_heart_rate scheduled__2024-05-15T17:00:00+00:00 [queued]>
[2024-05-16T17:05:01.948+0000] {taskinstance.py:1279} INFO - 
--------------------------------------------------------------------------------
[2024-05-16T17:05:01.949+0000] {taskinstance.py:1280} INFO - Starting attempt 2 of 2
[2024-05-16T17:05:01.949+0000] {taskinstance.py:1281} INFO - 
--------------------------------------------------------------------------------
[2024-05-16T17:05:01.956+0000] {taskinstance.py:1300} INFO - Executing <Task(PythonOperator): get_heart_rate> on 2024-05-15 17:00:00+00:00
[2024-05-16T17:05:01.961+0000] {standard_task_runner.py:55} INFO - Started process 396 to run task
[2024-05-16T17:05:01.965+0000] {standard_task_runner.py:82} INFO - Running: ['***', 'tasks', 'run', 'fitbit_data_pull', 'get_heart_rate', 'scheduled__2024-05-15T17:00:00+00:00', '--job-id', '34', '--raw', '--subdir', 'DAGS_FOLDER/fitbit_pull_dag.py', '--cfg-path', '/tmp/tmpnbel591j']
[2024-05-16T17:05:01.965+0000] {standard_task_runner.py:83} INFO - Job 34: Subtask get_heart_rate
[2024-05-16T17:05:02.021+0000] {task_command.py:388} INFO - Running <TaskInstance: fitbit_data_pull.get_heart_rate scheduled__2024-05-15T17:00:00+00:00 [running]> on host f88edbb2c20c
[2024-05-16T17:05:02.067+0000] {taskinstance.py:1509} INFO - Exporting the following env vars:
AIRFLOW_CTX_DAG_OWNER=***
AIRFLOW_CTX_DAG_ID=fitbit_data_pull
AIRFLOW_CTX_TASK_ID=get_heart_rate
AIRFLOW_CTX_EXECUTION_DATE=2024-05-15T17:00:00+00:00
AIRFLOW_CTX_TRY_NUMBER=2
AIRFLOW_CTX_DAG_RUN_ID=scheduled__2024-05-15T17:00:00+00:00
[2024-05-16T17:05:02.069+0000] {taskinstance.py:1768} ERROR - Task failed with exception
Traceback (most recent call last):
  File "/home/airflow/.local/lib/python3.7/site-packages/airflow/operators/python.py", line 175, in execute
    return_value = self.execute_callable()
  File "/home/airflow/.local/lib/python3.7/site-packages/airflow/operators/python.py", line 192, in execute_callable
    return self.python_callable(*self.op_args, **self.op_kwargs)
  File "/opt/airflow/dags/fitbit_pull_dag.py", line 39, in _get_yesterday_heartrate
    yesterday = datetime.datetime.now() - datetime.timedelta(days=1)
AttributeError: type object 'datetime.datetime' has no attribute 'datetime'
[2024-05-16T17:05:02.078+0000] {taskinstance.py:1323} INFO - Marking task as FAILED. dag_id=fitbit_data_pull, task_id=get_heart_rate, execution_date=20240515T170000, start_date=20240516T170501, end_date=20240516T170502
[2024-05-16T17:05:02.084+0000] {standard_task_runner.py:105} ERROR - Failed to execute job 34 for task get_heart_rate (type object 'datetime.datetime' has no attribute 'datetime'; 396)
[2024-05-16T17:05:02.096+0000] {local_task_job.py:208} INFO - Task exited with return code 1
[2024-05-16T17:05:02.114+0000] {taskinstance.py:2578} INFO - 0 downstream tasks scheduled from follow-on schedule check
