[2024-06-05T18:31:46.841+0000] {taskinstance.py:1083} INFO - Dependencies all met for <TaskInstance: fitbit_data_pull.get_heart_rate scheduled__2024-06-04T18:00:00+00:00 [queued]>
[2024-06-05T18:31:46.848+0000] {taskinstance.py:1083} INFO - Dependencies all met for <TaskInstance: fitbit_data_pull.get_heart_rate scheduled__2024-06-04T18:00:00+00:00 [queued]>
[2024-06-05T18:31:46.849+0000] {taskinstance.py:1279} INFO - 
--------------------------------------------------------------------------------
[2024-06-05T18:31:46.849+0000] {taskinstance.py:1280} INFO - Starting attempt 1 of 2
[2024-06-05T18:31:46.850+0000] {taskinstance.py:1281} INFO - 
--------------------------------------------------------------------------------
[2024-06-05T18:31:46.861+0000] {taskinstance.py:1300} INFO - Executing <Task(PythonOperator): get_heart_rate> on 2024-06-04 18:00:00+00:00
[2024-06-05T18:31:46.867+0000] {standard_task_runner.py:55} INFO - Started process 31798 to run task
[2024-06-05T18:31:46.871+0000] {standard_task_runner.py:82} INFO - Running: ['***', 'tasks', 'run', 'fitbit_data_pull', 'get_heart_rate', 'scheduled__2024-06-04T18:00:00+00:00', '--job-id', '75', '--raw', '--subdir', 'DAGS_FOLDER/fitbit_pull_dag.py', '--cfg-path', '/tmp/tmpsw5bhk38']
[2024-06-05T18:31:46.872+0000] {standard_task_runner.py:83} INFO - Job 75: Subtask get_heart_rate
[2024-06-05T18:31:46.969+0000] {task_command.py:388} INFO - Running <TaskInstance: fitbit_data_pull.get_heart_rate scheduled__2024-06-04T18:00:00+00:00 [running]> on host eb426318bb2e
[2024-06-05T18:31:47.035+0000] {taskinstance.py:1509} INFO - Exporting the following env vars:
AIRFLOW_CTX_DAG_OWNER=***
AIRFLOW_CTX_DAG_ID=fitbit_data_pull
AIRFLOW_CTX_TASK_ID=get_heart_rate
AIRFLOW_CTX_EXECUTION_DATE=2024-06-04T18:00:00+00:00
AIRFLOW_CTX_TRY_NUMBER=1
AIRFLOW_CTX_DAG_RUN_ID=scheduled__2024-06-04T18:00:00+00:00
[2024-06-05T18:31:47.072+0000] {taskinstance.py:1768} ERROR - Task failed with exception
Traceback (most recent call last):
  File "/home/airflow/.local/lib/python3.7/site-packages/urllib3/connection.py", line 175, in _new_conn
    (self._dns_host, self.port), self.timeout, **extra_kw
  File "/home/airflow/.local/lib/python3.7/site-packages/urllib3/util/connection.py", line 72, in create_connection
    for res in socket.getaddrinfo(host, port, family, socket.SOCK_STREAM):
  File "/usr/local/lib/python3.7/socket.py", line 752, in getaddrinfo
    for res in _socket.getaddrinfo(host, port, family, type, proto, flags):
socket.gaierror: [Errno -2] Name or service not known

During handling of the above exception, another exception occurred:

Traceback (most recent call last):
  File "/home/airflow/.local/lib/python3.7/site-packages/urllib3/connectionpool.py", line 710, in urlopen
    chunked=chunked,
  File "/home/airflow/.local/lib/python3.7/site-packages/urllib3/connectionpool.py", line 386, in _make_request
    self._validate_conn(conn)
  File "/home/airflow/.local/lib/python3.7/site-packages/urllib3/connectionpool.py", line 1042, in _validate_conn
    conn.connect()
  File "/home/airflow/.local/lib/python3.7/site-packages/urllib3/connection.py", line 358, in connect
    self.sock = conn = self._new_conn()
  File "/home/airflow/.local/lib/python3.7/site-packages/urllib3/connection.py", line 187, in _new_conn
    self, "Failed to establish a new connection: %s" % e
urllib3.exceptions.NewConnectionError: <urllib3.connection.HTTPSConnection object at 0xffff70772790>: Failed to establish a new connection: [Errno -2] Name or service not known

During handling of the above exception, another exception occurred:

Traceback (most recent call last):
  File "/home/airflow/.local/lib/python3.7/site-packages/requests/adapters.py", line 499, in send
    timeout=timeout,
  File "/home/airflow/.local/lib/python3.7/site-packages/urllib3/connectionpool.py", line 788, in urlopen
    method, url, error=e, _pool=self, _stacktrace=sys.exc_info()[2]
  File "/home/airflow/.local/lib/python3.7/site-packages/urllib3/util/retry.py", line 592, in increment
    raise MaxRetryError(_pool, url, error or ResponseError(cause))
urllib3.exceptions.MaxRetryError: HTTPSConnectionPool(host='api.fitbit.com', port=443): Max retries exceeded with url: /1/user/-/activities/heart/date/2024-06-04/1d/1min/time/00:00/23:59.json (Caused by NewConnectionError('<urllib3.connection.HTTPSConnection object at 0xffff70772790>: Failed to establish a new connection: [Errno -2] Name or service not known'))

During handling of the above exception, another exception occurred:

Traceback (most recent call last):
  File "/home/airflow/.local/lib/python3.7/site-packages/airflow/operators/python.py", line 175, in execute
    return_value = self.execute_callable()
  File "/home/airflow/.local/lib/python3.7/site-packages/airflow/operators/python.py", line 192, in execute_callable
    return self.python_callable(*self.op_args, **self.op_kwargs)
  File "/opt/airflow/dags/fitbit_pull_dag.py", line 40, in _get_yesterday_heartrate
    response = requests.get(url, headers=headers)
  File "/home/airflow/.local/lib/python3.7/site-packages/requests/api.py", line 73, in get
    return request("get", url, params=params, **kwargs)
  File "/home/airflow/.local/lib/python3.7/site-packages/requests/api.py", line 59, in request
    return session.request(method=method, url=url, **kwargs)
  File "/home/airflow/.local/lib/python3.7/site-packages/requests/sessions.py", line 587, in request
    resp = self.send(prep, **send_kwargs)
  File "/home/airflow/.local/lib/python3.7/site-packages/requests/sessions.py", line 701, in send
    r = adapter.send(request, **kwargs)
  File "/home/airflow/.local/lib/python3.7/site-packages/requests/adapters.py", line 565, in send
    raise ConnectionError(e, request=request)
requests.exceptions.ConnectionError: HTTPSConnectionPool(host='api.fitbit.com', port=443): Max retries exceeded with url: /1/user/-/activities/heart/date/2024-06-04/1d/1min/time/00:00/23:59.json (Caused by NewConnectionError('<urllib3.connection.HTTPSConnection object at 0xffff70772790>: Failed to establish a new connection: [Errno -2] Name or service not known'))
[2024-06-05T18:31:47.086+0000] {taskinstance.py:1323} INFO - Marking task as UP_FOR_RETRY. dag_id=fitbit_data_pull, task_id=get_heart_rate, execution_date=20240604T180000, start_date=20240605T183146, end_date=20240605T183147
[2024-06-05T18:31:47.099+0000] {standard_task_runner.py:105} ERROR - Failed to execute job 75 for task get_heart_rate (HTTPSConnectionPool(host='api.fitbit.com', port=443): Max retries exceeded with url: /1/user/-/activities/heart/date/2024-06-04/1d/1min/time/00:00/23:59.json (Caused by NewConnectionError('<urllib3.connection.HTTPSConnection object at 0xffff70772790>: Failed to establish a new connection: [Errno -2] Name or service not known')); 31798)
[2024-06-05T18:31:47.124+0000] {local_task_job.py:208} INFO - Task exited with return code 1
[2024-06-05T18:31:47.142+0000] {taskinstance.py:2578} INFO - 0 downstream tasks scheduled from follow-on schedule check
