[2024-05-16T18:10:41.179+0000] {taskinstance.py:1083} INFO - Dependencies all met for <TaskInstance: fitbit_data_pull.get_heart_rate manual__2024-05-16T18:10:39.935343+00:00 [queued]>
[2024-05-16T18:10:41.186+0000] {taskinstance.py:1083} INFO - Dependencies all met for <TaskInstance: fitbit_data_pull.get_heart_rate manual__2024-05-16T18:10:39.935343+00:00 [queued]>
[2024-05-16T18:10:41.186+0000] {taskinstance.py:1279} INFO - 
--------------------------------------------------------------------------------
[2024-05-16T18:10:41.187+0000] {taskinstance.py:1280} INFO - Starting attempt 1 of 2
[2024-05-16T18:10:41.187+0000] {taskinstance.py:1281} INFO - 
--------------------------------------------------------------------------------
[2024-05-16T18:10:41.196+0000] {taskinstance.py:1300} INFO - Executing <Task(PythonOperator): get_heart_rate> on 2024-05-16 18:10:39.935343+00:00
[2024-05-16T18:10:41.201+0000] {standard_task_runner.py:55} INFO - Started process 2066 to run task
[2024-05-16T18:10:41.205+0000] {standard_task_runner.py:82} INFO - Running: ['***', 'tasks', 'run', 'fitbit_data_pull', 'get_heart_rate', 'manual__2024-05-16T18:10:39.935343+00:00', '--job-id', '45', '--raw', '--subdir', 'DAGS_FOLDER/fitbit_pull_dag.py', '--cfg-path', '/tmp/tmpkao_zqyr']
[2024-05-16T18:10:41.206+0000] {standard_task_runner.py:83} INFO - Job 45: Subtask get_heart_rate
[2024-05-16T18:10:41.271+0000] {task_command.py:388} INFO - Running <TaskInstance: fitbit_data_pull.get_heart_rate manual__2024-05-16T18:10:39.935343+00:00 [running]> on host f88edbb2c20c
[2024-05-16T18:10:41.331+0000] {taskinstance.py:1509} INFO - Exporting the following env vars:
AIRFLOW_CTX_DAG_OWNER=***
AIRFLOW_CTX_DAG_ID=fitbit_data_pull
AIRFLOW_CTX_TASK_ID=get_heart_rate
AIRFLOW_CTX_EXECUTION_DATE=2024-05-16T18:10:39.935343+00:00
AIRFLOW_CTX_TRY_NUMBER=1
AIRFLOW_CTX_DAG_RUN_ID=manual__2024-05-16T18:10:39.935343+00:00
[2024-05-16T18:10:41.922+0000] {taskinstance.py:1768} ERROR - Task failed with exception
Traceback (most recent call last):
  File "/home/airflow/.local/lib/python3.7/site-packages/airflow/operators/python.py", line 175, in execute
    return_value = self.execute_callable()
  File "/home/airflow/.local/lib/python3.7/site-packages/airflow/operators/python.py", line 192, in execute_callable
    return self.python_callable(*self.op_args, **self.op_kwargs)
  File "/opt/airflow/dags/fitbit_pull_dag.py", line 51, in _get_yesterday_heartrate
    df_heartrate.to_csv(f'{output_dir}/heartrate_{yesterday}.csv',index=False)
  File "/home/airflow/.local/lib/python3.7/site-packages/pandas/core/generic.py", line 3482, in to_csv
    storage_options=storage_options,
  File "/home/airflow/.local/lib/python3.7/site-packages/pandas/io/formats/format.py", line 1105, in to_csv
    csv_formatter.save()
  File "/home/airflow/.local/lib/python3.7/site-packages/pandas/io/formats/csvs.py", line 243, in save
    storage_options=self.storage_options,
  File "/home/airflow/.local/lib/python3.7/site-packages/pandas/io/common.py", line 707, in get_handle
    newline="",
FileNotFoundError: [Errno 2] No such file or directory: '/opt/airflow/output/heartrate_2024-05-15.csv'
[2024-05-16T18:10:41.935+0000] {taskinstance.py:1323} INFO - Marking task as UP_FOR_RETRY. dag_id=fitbit_data_pull, task_id=get_heart_rate, execution_date=20240516T181039, start_date=20240516T181041, end_date=20240516T181041
[2024-05-16T18:10:41.942+0000] {standard_task_runner.py:105} ERROR - Failed to execute job 45 for task get_heart_rate ([Errno 2] No such file or directory: '/opt/airflow/output/heartrate_2024-05-15.csv'; 2066)
[2024-05-16T18:10:41.998+0000] {local_task_job.py:208} INFO - Task exited with return code 1
[2024-05-16T18:10:42.012+0000] {taskinstance.py:2578} INFO - 0 downstream tasks scheduled from follow-on schedule check
