[2024-05-15T17:05:01.507+0000] {taskinstance.py:1083} INFO - Dependencies all met for <TaskInstance: fitbit_data_pull.get_heart_rate scheduled__2024-05-14T17:00:00+00:00 [queued]>
[2024-05-15T17:05:01.513+0000] {taskinstance.py:1083} INFO - Dependencies all met for <TaskInstance: fitbit_data_pull.get_heart_rate scheduled__2024-05-14T17:00:00+00:00 [queued]>
[2024-05-15T17:05:01.513+0000] {taskinstance.py:1279} INFO - 
--------------------------------------------------------------------------------
[2024-05-15T17:05:01.514+0000] {taskinstance.py:1280} INFO - Starting attempt 2 of 2
[2024-05-15T17:05:01.514+0000] {taskinstance.py:1281} INFO - 
--------------------------------------------------------------------------------
[2024-05-15T17:05:01.523+0000] {taskinstance.py:1300} INFO - Executing <Task(PythonOperator): get_heart_rate> on 2024-05-14 17:00:00+00:00
[2024-05-15T17:05:01.528+0000] {standard_task_runner.py:55} INFO - Started process 38869 to run task
[2024-05-15T17:05:01.531+0000] {standard_task_runner.py:82} INFO - Running: ['***', 'tasks', 'run', 'fitbit_data_pull', 'get_heart_rate', 'scheduled__2024-05-14T17:00:00+00:00', '--job-id', '30', '--raw', '--subdir', 'DAGS_FOLDER/fitbit_pull_dag.py', '--cfg-path', '/tmp/tmp85b1bdo6']
[2024-05-15T17:05:01.532+0000] {standard_task_runner.py:83} INFO - Job 30: Subtask get_heart_rate
[2024-05-15T17:05:01.590+0000] {task_command.py:388} INFO - Running <TaskInstance: fitbit_data_pull.get_heart_rate scheduled__2024-05-14T17:00:00+00:00 [running]> on host f88edbb2c20c
[2024-05-15T17:05:01.636+0000] {taskinstance.py:1509} INFO - Exporting the following env vars:
AIRFLOW_CTX_DAG_OWNER=***
AIRFLOW_CTX_DAG_ID=fitbit_data_pull
AIRFLOW_CTX_TASK_ID=get_heart_rate
AIRFLOW_CTX_EXECUTION_DATE=2024-05-14T17:00:00+00:00
AIRFLOW_CTX_TRY_NUMBER=2
AIRFLOW_CTX_DAG_RUN_ID=scheduled__2024-05-14T17:00:00+00:00
[2024-05-15T17:05:01.638+0000] {taskinstance.py:1768} ERROR - Task failed with exception
Traceback (most recent call last):
  File "/home/airflow/.local/lib/python3.7/site-packages/airflow/operators/python.py", line 175, in execute
    return_value = self.execute_callable()
  File "/home/airflow/.local/lib/python3.7/site-packages/airflow/operators/python.py", line 192, in execute_callable
    return self.python_callable(*self.op_args, **self.op_kwargs)
  File "/opt/airflow/dags/fitbit_pull_dag.py", line 39, in _get_yesterday_heartrate
    yesterday = datetime.datetime.now() - datetime.timedelta(days=1)
AttributeError: type object 'datetime.datetime' has no attribute 'datetime'
[2024-05-15T17:05:01.646+0000] {taskinstance.py:1323} INFO - Marking task as FAILED. dag_id=fitbit_data_pull, task_id=get_heart_rate, execution_date=20240514T170000, start_date=20240515T170501, end_date=20240515T170501
[2024-05-15T17:05:01.653+0000] {standard_task_runner.py:105} ERROR - Failed to execute job 30 for task get_heart_rate (type object 'datetime.datetime' has no attribute 'datetime'; 38869)
[2024-05-15T17:05:01.713+0000] {local_task_job.py:208} INFO - Task exited with return code 1
[2024-05-15T17:05:01.732+0000] {taskinstance.py:2578} INFO - 0 downstream tasks scheduled from follow-on schedule check
