[2024-05-16T18:27:51.637+0000] {taskinstance.py:1083} INFO - Dependencies all met for <TaskInstance: fitbit_data_pull.get_heart_rate manual__2024-05-16T18:27:50.428599+00:00 [queued]>
[2024-05-16T18:27:51.643+0000] {taskinstance.py:1083} INFO - Dependencies all met for <TaskInstance: fitbit_data_pull.get_heart_rate manual__2024-05-16T18:27:50.428599+00:00 [queued]>
[2024-05-16T18:27:51.644+0000] {taskinstance.py:1279} INFO - 
--------------------------------------------------------------------------------
[2024-05-16T18:27:51.644+0000] {taskinstance.py:1280} INFO - Starting attempt 1 of 2
[2024-05-16T18:27:51.645+0000] {taskinstance.py:1281} INFO - 
--------------------------------------------------------------------------------
[2024-05-16T18:27:51.655+0000] {taskinstance.py:1300} INFO - Executing <Task(PythonOperator): get_heart_rate> on 2024-05-16 18:27:50.428599+00:00
[2024-05-16T18:27:51.660+0000] {standard_task_runner.py:55} INFO - Started process 305 to run task
[2024-05-16T18:27:51.664+0000] {standard_task_runner.py:82} INFO - Running: ['***', 'tasks', 'run', 'fitbit_data_pull', 'get_heart_rate', 'manual__2024-05-16T18:27:50.428599+00:00', '--job-id', '51', '--raw', '--subdir', 'DAGS_FOLDER/fitbit_pull_dag.py', '--cfg-path', '/tmp/tmpt0gqsid5']
[2024-05-16T18:27:51.665+0000] {standard_task_runner.py:83} INFO - Job 51: Subtask get_heart_rate
[2024-05-16T18:27:51.736+0000] {task_command.py:388} INFO - Running <TaskInstance: fitbit_data_pull.get_heart_rate manual__2024-05-16T18:27:50.428599+00:00 [running]> on host eb426318bb2e
[2024-05-16T18:27:51.786+0000] {taskinstance.py:1509} INFO - Exporting the following env vars:
AIRFLOW_CTX_DAG_OWNER=***
AIRFLOW_CTX_DAG_ID=fitbit_data_pull
AIRFLOW_CTX_TASK_ID=get_heart_rate
AIRFLOW_CTX_EXECUTION_DATE=2024-05-16T18:27:50.428599+00:00
AIRFLOW_CTX_TRY_NUMBER=1
AIRFLOW_CTX_DAG_RUN_ID=manual__2024-05-16T18:27:50.428599+00:00
[2024-05-16T18:27:52.306+0000] {fitbit_pull_dag.py:53} INFO - Successfully extracted data for 2024-05-15:          date      time  heartrate
0  2024-05-15  00:00:00         62
1  2024-05-15  00:01:00         67
2  2024-05-15  00:02:00         62
3  2024-05-15  00:03:00         62
4  2024-05-15  00:04:00         61
[2024-05-16T18:27:52.307+0000] {fitbit_pull_dag.py:55} INFO - Storing file /opt/***/output/heartrate_2024-05-15.csv
[2024-05-16T18:27:52.310+0000] {taskinstance.py:1768} ERROR - Task failed with exception
Traceback (most recent call last):
  File "/home/airflow/.local/lib/python3.7/site-packages/airflow/operators/python.py", line 175, in execute
    return_value = self.execute_callable()
  File "/home/airflow/.local/lib/python3.7/site-packages/airflow/operators/python.py", line 192, in execute_callable
    return self.python_callable(*self.op_args, **self.op_kwargs)
  File "/opt/airflow/dags/fitbit_pull_dag.py", line 57, in _get_yesterday_heartrate
    df_heartrate.to_csv(f'/opt/airlow/output/heartrate_{yesterday}.csv',index=False)
  File "/home/airflow/.local/lib/python3.7/site-packages/pandas/core/generic.py", line 3482, in to_csv
    storage_options=storage_options,
  File "/home/airflow/.local/lib/python3.7/site-packages/pandas/io/formats/format.py", line 1105, in to_csv
    csv_formatter.save()
  File "/home/airflow/.local/lib/python3.7/site-packages/pandas/io/formats/csvs.py", line 243, in save
    storage_options=self.storage_options,
  File "/home/airflow/.local/lib/python3.7/site-packages/pandas/io/common.py", line 707, in get_handle
    newline="",
FileNotFoundError: [Errno 2] No such file or directory: '/opt/airlow/output/heartrate_2024-05-15.csv'
[2024-05-16T18:27:52.321+0000] {taskinstance.py:1323} INFO - Marking task as UP_FOR_RETRY. dag_id=fitbit_data_pull, task_id=get_heart_rate, execution_date=20240516T182750, start_date=20240516T182751, end_date=20240516T182752
[2024-05-16T18:27:52.330+0000] {standard_task_runner.py:105} ERROR - Failed to execute job 51 for task get_heart_rate ([Errno 2] No such file or directory: '/opt/airlow/output/heartrate_2024-05-15.csv'; 305)
[2024-05-16T18:27:52.370+0000] {local_task_job.py:208} INFO - Task exited with return code 1
[2024-05-16T18:27:52.385+0000] {taskinstance.py:2578} INFO - 0 downstream tasks scheduled from follow-on schedule check
